2024-04-24 02:37:36,570:ERROR:discord.ext.commands.bot: Ignoring exception in command add
Traceback (most recent call last):
  File "C:\Users\maddi\PycharmProjects\pythonProject\venv\Lib\site-packages\discord\ext\commands\core.py", line 235, in wrapped
    ret = await coro(*args, **kwargs)
          ^^^^^^^^^^^^^^^^^^^^^^^^^^^
  File "C:\Users\maddi\PycharmProjects\Discord_SneekPeekBot\cogs\cogs_example.py", line 19, in add
    await ctx.send(TestFlags.left + TestFlags.right)
                   ^^^^^^^^^^^^^^
AttributeError: type object 'TestFlags' has no attribute 'left'

The above exception was the direct cause of the following exception:

Traceback (most recent call last):
  File "C:\Users\maddi\PycharmProjects\pythonProject\venv\Lib\site-packages\discord\ext\commands\bot.py", line 1350, in invoke
    await ctx.command.invoke(ctx)
  File "C:\Users\maddi\PycharmProjects\pythonProject\venv\Lib\site-packages\discord\ext\commands\core.py", line 1029, in invoke
    await injected(*ctx.args, **ctx.kwargs)  # type: ignore
    ^^^^^^^^^^^^^^^^^^^^^^^^^^^^^^^^^^^^^^^
  File "C:\Users\maddi\PycharmProjects\pythonProject\venv\Lib\site-packages\discord\ext\commands\core.py", line 244, in wrapped
    raise CommandInvokeError(exc) from exc
discord.ext.commands.errors.CommandInvokeError: Command raised an exception: AttributeError: type object 'TestFlags' has no attribute 'left'
2024-04-24 02:39:02,636:ERROR:discord.ext.commands.bot: Ignoring exception in command add
Traceback (most recent call last):
  File "C:\Users\maddi\PycharmProjects\pythonProject\venv\Lib\site-packages\discord\ext\commands\bot.py", line 1350, in invoke
    await ctx.command.invoke(ctx)
  File "C:\Users\maddi\PycharmProjects\pythonProject\venv\Lib\site-packages\discord\ext\commands\core.py", line 1021, in invoke
    await self.prepare(ctx)
  File "C:\Users\maddi\PycharmProjects\pythonProject\venv\Lib\site-packages\discord\ext\commands\core.py", line 938, in prepare
    await self._parse_arguments(ctx)
  File "C:\Users\maddi\PycharmProjects\pythonProject\venv\Lib\site-packages\discord\ext\commands\hybrid.py", line 531, in _parse_arguments
    return await super()._parse_arguments(ctx)
           ^^^^^^^^^^^^^^^^^^^^^^^^^^^^^^^^^^^
  File "C:\Users\maddi\PycharmProjects\pythonProject\venv\Lib\site-packages\discord\ext\commands\core.py", line 845, in _parse_arguments
    transformed = await self.transform(ctx, param, attachments)
                  ^^^^^^^^^^^^^^^^^^^^^^^^^^^^^^^^^^^^^^^^^^^^^
  File "C:\Users\maddi\PycharmProjects\pythonProject\venv\Lib\site-packages\discord\ext\commands\core.py", line 697, in transform
    raise MissingRequiredArgument(param)
discord.ext.commands.errors.MissingRequiredArgument: left is a required argument that is missing.
2024-04-24 02:40:11,072:ERROR:discord.ext.commands.bot: Ignoring exception in command add
Traceback (most recent call last):
  File "C:\Users\maddi\PycharmProjects\pythonProject\venv\Lib\site-packages\discord\ext\commands\bot.py", line 1350, in invoke
    await ctx.command.invoke(ctx)
  File "C:\Users\maddi\PycharmProjects\pythonProject\venv\Lib\site-packages\discord\ext\commands\core.py", line 1021, in invoke
    await self.prepare(ctx)
  File "C:\Users\maddi\PycharmProjects\pythonProject\venv\Lib\site-packages\discord\ext\commands\core.py", line 938, in prepare
    await self._parse_arguments(ctx)
  File "C:\Users\maddi\PycharmProjects\pythonProject\venv\Lib\site-packages\discord\ext\commands\hybrid.py", line 531, in _parse_arguments
    return await super()._parse_arguments(ctx)
           ^^^^^^^^^^^^^^^^^^^^^^^^^^^^^^^^^^^
  File "C:\Users\maddi\PycharmProjects\pythonProject\venv\Lib\site-packages\discord\ext\commands\core.py", line 845, in _parse_arguments
    transformed = await self.transform(ctx, param, attachments)
                  ^^^^^^^^^^^^^^^^^^^^^^^^^^^^^^^^^^^^^^^^^^^^^
  File "C:\Users\maddi\PycharmProjects\pythonProject\venv\Lib\site-packages\discord\ext\commands\core.py", line 697, in transform
    raise MissingRequiredArgument(param)
discord.ext.commands.errors.MissingRequiredArgument: left is a required argument that is missing.
2024-04-24 02:47:16,165:ERROR:discord.client: Ignoring exception in on_ready
Traceback (most recent call last):
  File "C:\Users\maddi\PycharmProjects\pythonProject\venv\Lib\site-packages\discord\client.py", line 441, in _run_event
    await coro(*args, **kwargs)
  File "C:\Users\maddi\PycharmProjects\Discord_SneekPeekBot\main.py", line 65, in on_ready
    await bot.add_cog(cogs.SneekCommands(bot))
                      ^^^^^^^^^^^^^^^^^^
AttributeError: module 'cogs' has no attribute 'SneekCommands'
2024-04-24 02:47:22,098:ERROR:discord.ext.commands.bot: Ignoring exception in command None
discord.ext.commands.errors.CommandNotFound: Command "add" is not found
2024-04-24 02:49:37,710:ERROR:discord.client: Ignoring exception in on_ready
Traceback (most recent call last):
  File "C:\Users\maddi\PycharmProjects\pythonProject\venv\Lib\site-packages\discord\client.py", line 441, in _run_event
    await coro(*args, **kwargs)
  File "C:\Users\maddi\PycharmProjects\Discord_SneekPeekBot\main.py", line 65, in on_ready
    await bot.add_cog(sneek_commands.SneekCog(bot))
                      ^^^^^^^^^^^^^^^^^^^^^^^
AttributeError: module 'cogs.sneek_commands' has no attribute 'SneekCog'
2024-04-24 02:50:08,051:ERROR:discord.client: Ignoring exception in on_ready
Traceback (most recent call last):
  File "C:\Users\maddi\PycharmProjects\pythonProject\venv\Lib\site-packages\discord\client.py", line 441, in _run_event
    await coro(*args, **kwargs)
  File "C:\Users\maddi\PycharmProjects\Discord_SneekPeekBot\main.py", line 65, in on_ready
    await bot.add_cog(sneek_commands.SneekCog(bot))
                      ^^^^^^^^^^^^^^^^^^^^^^^^^^^^
TypeError: SneekCog.__init__() takes 1 positional argument but 2 were given
2024-04-25 00:49:56,008:ERROR:discord.client: Ignoring exception in on_ready
Traceback (most recent call last):
  File "C:\Users\maddi\PycharmProjects\pythonProject\venv\Lib\site-packages\discord\client.py", line 441, in _run_event
    await coro(*args, **kwargs)
  File "C:\Users\maddi\PycharmProjects\Discord_SneekPeekBot\sneek_bot.py", line 10, in on_ready
    print(f'Logged in as {bot.user} (ID: {bot.user.id})')
                          ^^^
NameError: name 'bot' is not defined
2024-04-25 00:59:39,310:ERROR:discord.client: Ignoring exception in on_ready
Traceback (most recent call last):
  File "C:\Users\maddi\PycharmProjects\pythonProject\venv\Lib\site-packages\discord\client.py", line 441, in _run_event
    await coro(*args, **kwargs)
  File "C:\Users\maddi\PycharmProjects\Discord_SneekPeekBot\sneekbot.py", line 26, in on_ready
    logger.info("loading cogs...")
    ^^^^^^^^^^^
AttributeError: module 'logger' has no attribute 'info'
2024-04-25 01:01:36,041:ERROR:discord.client: Ignoring exception in on_ready
Traceback (most recent call last):
  File "C:\Users\maddi\PycharmProjects\pythonProject\venv\Lib\site-packages\discord\client.py", line 441, in _run_event
    await coro(*args, **kwargs)
  File "C:\Users\maddi\PycharmProjects\Discord_SneekPeekBot\sneekbot.py", line 27, in on_ready
    logger.info("loading cogs...")
    ^^^^^^
NameError: name 'logger' is not defined
2024-04-25 01:02:42,611:ERROR:discord.client: Ignoring exception in on_ready
Traceback (most recent call last):
  File "C:\Users\maddi\PycharmProjects\pythonProject\venv\Lib\site-packages\discord\client.py", line 441, in _run_event
    await coro(*args, **kwargs)
  File "C:\Users\maddi\PycharmProjects\Discord_SneekPeekBot\sneekbot.py", line 27, in on_ready
    self.logger.info("loading cogs...")
    ^^^^^^^^^^^
AttributeError: 'SneekBot' object has no attribute 'logger'
2024-04-25 01:07:33,642:ERROR:discord.ext.commands.bot: Ignoring exception in command None
discord.ext.commands.errors.CommandNotFound: Command "test_command" is not found
2024-04-25 01:09:20,945:ERROR:discord.ext.commands.bot: Ignoring exception in command None
discord.ext.commands.errors.CommandNotFound: Command "test_command" is not found
2024-04-25 01:11:52,851:ERROR:discord.ext.commands.bot: Ignoring exception in command None
discord.ext.commands.errors.CommandNotFound: Command "test_command" is not found
2024-04-25 01:13:51,265:ERROR:discord.ext.commands.bot: Ignoring exception in command None
discord.ext.commands.errors.CommandNotFound: Command "test" is not found
2024-04-25 01:15:17,678:ERROR:discord.ext.commands.bot: Ignoring exception in command None
discord.ext.commands.errors.CommandNotFound: Command "test" is not found
2024-04-30 00:29:34,211:ERROR:discord.ext.commands.bot: Ignoring exception in command sneek
Traceback (most recent call last):
  File "C:\Users\maddi\PycharmProjects\pythonProject\venv\Lib\site-packages\discord\ext\commands\core.py", line 235, in wrapped
    ret = await coro(*args, **kwargs)
          ^^^^^^^^^^^^^^^^^^^^^^^^^^^
  File "C:\Users\maddi\PycharmProjects\Discord_SneekPeekBot\cogs\sneek_commands.py", line 28, in sneek
    film = movie.Rank
           ^^^^^^^^^^
AttributeError: 'dict' object has no attribute 'Rank'

The above exception was the direct cause of the following exception:

Traceback (most recent call last):
  File "C:\Users\maddi\PycharmProjects\pythonProject\venv\Lib\site-packages\discord\ext\commands\bot.py", line 1350, in invoke
    await ctx.command.invoke(ctx)
  File "C:\Users\maddi\PycharmProjects\pythonProject\venv\Lib\site-packages\discord\ext\commands\core.py", line 1029, in invoke
    await injected(*ctx.args, **ctx.kwargs)  # type: ignore
    ^^^^^^^^^^^^^^^^^^^^^^^^^^^^^^^^^^^^^^^
  File "C:\Users\maddi\PycharmProjects\pythonProject\venv\Lib\site-packages\discord\ext\commands\core.py", line 244, in wrapped
    raise CommandInvokeError(exc) from exc
discord.ext.commands.errors.CommandInvokeError: Command raised an exception: AttributeError: 'dict' object has no attribute 'Rank'
2024-04-30 01:14:14,879:ERROR:discord.ext.commands.bot: Ignoring exception in command sneek
Traceback (most recent call last):
  File "C:\Users\maddi\PycharmProjects\pythonProject\venv\Lib\site-packages\discord\ext\commands\core.py", line 235, in wrapped
    ret = await coro(*args, **kwargs)
          ^^^^^^^^^^^^^^^^^^^^^^^^^^^
  File "C:\Users\maddi\PycharmProjects\Discord_SneekPeekBot\cogs\sneek_commands.py", line 23, in sneek
    movies = extract.scrape_sneak()
             ^^^^^^^^^^^^^^^^^^^^^^
  File "C:\Users\maddi\PycharmProjects\Discord_SneekPeekBot\jkunze\extract.py", line 31, in scrape_sneak
    chance = columns[1].contents.width
             ^^^^^^^^^^^^^^^^^^^^^^^^^
AttributeError: 'list' object has no attribute 'width'

The above exception was the direct cause of the following exception:

Traceback (most recent call last):
  File "C:\Users\maddi\PycharmProjects\pythonProject\venv\Lib\site-packages\discord\ext\commands\bot.py", line 1350, in invoke
    await ctx.command.invoke(ctx)
  File "C:\Users\maddi\PycharmProjects\pythonProject\venv\Lib\site-packages\discord\ext\commands\core.py", line 1029, in invoke
    await injected(*ctx.args, **ctx.kwargs)  # type: ignore
    ^^^^^^^^^^^^^^^^^^^^^^^^^^^^^^^^^^^^^^^
  File "C:\Users\maddi\PycharmProjects\pythonProject\venv\Lib\site-packages\discord\ext\commands\core.py", line 244, in wrapped
    raise CommandInvokeError(exc) from exc
discord.ext.commands.errors.CommandInvokeError: Command raised an exception: AttributeError: 'list' object has no attribute 'width'
2024-04-30 01:16:15,419:ERROR:discord.ext.commands.bot: Ignoring exception in command sneek
Traceback (most recent call last):
  File "C:\Users\maddi\PycharmProjects\pythonProject\venv\Lib\site-packages\discord\ext\commands\core.py", line 235, in wrapped
    ret = await coro(*args, **kwargs)
          ^^^^^^^^^^^^^^^^^^^^^^^^^^^
  File "C:\Users\maddi\PycharmProjects\Discord_SneekPeekBot\cogs\sneek_commands.py", line 23, in sneek
    movies = extract.scrape_sneak()
             ^^^^^^^^^^^^^^^^^^^^^^
  File "C:\Users\maddi\PycharmProjects\Discord_SneekPeekBot\jkunze\extract.py", line 31, in scrape_sneak
    chance = columns[1].contents.style
             ^^^^^^^^^^^^^^^^^^^^^^^^^
AttributeError: 'list' object has no attribute 'style'

The above exception was the direct cause of the following exception:

Traceback (most recent call last):
  File "C:\Users\maddi\PycharmProjects\pythonProject\venv\Lib\site-packages\discord\ext\commands\bot.py", line 1350, in invoke
    await ctx.command.invoke(ctx)
  File "C:\Users\maddi\PycharmProjects\pythonProject\venv\Lib\site-packages\discord\ext\commands\core.py", line 1029, in invoke
    await injected(*ctx.args, **ctx.kwargs)  # type: ignore
    ^^^^^^^^^^^^^^^^^^^^^^^^^^^^^^^^^^^^^^^
  File "C:\Users\maddi\PycharmProjects\pythonProject\venv\Lib\site-packages\discord\ext\commands\core.py", line 244, in wrapped
    raise CommandInvokeError(exc) from exc
discord.ext.commands.errors.CommandInvokeError: Command raised an exception: AttributeError: 'list' object has no attribute 'style'
2024-04-30 01:16:58,453:ERROR:discord.ext.commands.bot: Ignoring exception in command sneek
Traceback (most recent call last):
  File "C:\Users\maddi\PycharmProjects\pythonProject\venv\Lib\site-packages\discord\ext\commands\core.py", line 235, in wrapped
    ret = await coro(*args, **kwargs)
          ^^^^^^^^^^^^^^^^^^^^^^^^^^^
  File "C:\Users\maddi\PycharmProjects\Discord_SneekPeekBot\cogs\sneek_commands.py", line 23, in sneek
    movies = extract.scrape_sneak()
             ^^^^^^^^^^^^^^^^^^^^^^
  File "C:\Users\maddi\PycharmProjects\Discord_SneekPeekBot\jkunze\extract.py", line 31, in scrape_sneak
    chance = columns[1].contents[1]
             ~~~~~~~~~~~~~~~~~~~^^^
IndexError: list index out of range

The above exception was the direct cause of the following exception:

Traceback (most recent call last):
  File "C:\Users\maddi\PycharmProjects\pythonProject\venv\Lib\site-packages\discord\ext\commands\bot.py", line 1350, in invoke
    await ctx.command.invoke(ctx)
  File "C:\Users\maddi\PycharmProjects\pythonProject\venv\Lib\site-packages\discord\ext\commands\core.py", line 1029, in invoke
    await injected(*ctx.args, **ctx.kwargs)  # type: ignore
    ^^^^^^^^^^^^^^^^^^^^^^^^^^^^^^^^^^^^^^^
  File "C:\Users\maddi\PycharmProjects\pythonProject\venv\Lib\site-packages\discord\ext\commands\core.py", line 244, in wrapped
    raise CommandInvokeError(exc) from exc
discord.ext.commands.errors.CommandInvokeError: Command raised an exception: IndexError: list index out of range
2024-04-30 01:21:34,521:ERROR:discord.ext.commands.bot: Ignoring exception in command sneek
Traceback (most recent call last):
  File "C:\Users\maddi\PycharmProjects\pythonProject\venv\Lib\site-packages\discord\ext\commands\core.py", line 235, in wrapped
    ret = await coro(*args, **kwargs)
          ^^^^^^^^^^^^^^^^^^^^^^^^^^^
  File "C:\Users\maddi\PycharmProjects\Discord_SneekPeekBot\cogs\sneek_commands.py", line 23, in sneek
    movies = extract.scrape_sneak()
             ^^^^^^^^^^^^^^^^^^^^^^
  File "C:\Users\maddi\PycharmProjects\Discord_SneekPeekBot\jkunze\extract.py", line 31, in scrape_sneak
    chance = columns[1].contents[0].div.attrs
             ^^^^^^^^^^^^^^^^^^^^^^^^^^^^^^^^
AttributeError: 'NoneType' object has no attribute 'attrs'

The above exception was the direct cause of the following exception:

Traceback (most recent call last):
  File "C:\Users\maddi\PycharmProjects\pythonProject\venv\Lib\site-packages\discord\ext\commands\bot.py", line 1350, in invoke
    await ctx.command.invoke(ctx)
  File "C:\Users\maddi\PycharmProjects\pythonProject\venv\Lib\site-packages\discord\ext\commands\core.py", line 1029, in invoke
    await injected(*ctx.args, **ctx.kwargs)  # type: ignore
    ^^^^^^^^^^^^^^^^^^^^^^^^^^^^^^^^^^^^^^^
  File "C:\Users\maddi\PycharmProjects\pythonProject\venv\Lib\site-packages\discord\ext\commands\core.py", line 244, in wrapped
    raise CommandInvokeError(exc) from exc
discord.ext.commands.errors.CommandInvokeError: Command raised an exception: AttributeError: 'NoneType' object has no attribute 'attrs'
2024-04-30 01:25:09,928:ERROR:discord.ext.commands.bot: Ignoring exception in command sneek
Traceback (most recent call last):
  File "C:\Users\maddi\PycharmProjects\pythonProject\venv\Lib\site-packages\discord\ext\commands\core.py", line 235, in wrapped
    ret = await coro(*args, **kwargs)
          ^^^^^^^^^^^^^^^^^^^^^^^^^^^
  File "C:\Users\maddi\PycharmProjects\Discord_SneekPeekBot\cogs\sneek_commands.py", line 23, in sneek
    movies = extract.scrape_sneak()
             ^^^^^^^^^^^^^^^^^^^^^^
  File "C:\Users\maddi\PycharmProjects\Discord_SneekPeekBot\jkunze\extract.py", line 33, in scrape_sneak
    test_chance = columns[1].contents[0].attrs.style
                  ^^^^^^^^^^^^^^^^^^^^^^^^^^^^^^^^^^
AttributeError: 'dict' object has no attribute 'style'

The above exception was the direct cause of the following exception:

Traceback (most recent call last):
  File "C:\Users\maddi\PycharmProjects\pythonProject\venv\Lib\site-packages\discord\ext\commands\bot.py", line 1350, in invoke
    await ctx.command.invoke(ctx)
  File "C:\Users\maddi\PycharmProjects\pythonProject\venv\Lib\site-packages\discord\ext\commands\core.py", line 1029, in invoke
    await injected(*ctx.args, **ctx.kwargs)  # type: ignore
    ^^^^^^^^^^^^^^^^^^^^^^^^^^^^^^^^^^^^^^^
  File "C:\Users\maddi\PycharmProjects\pythonProject\venv\Lib\site-packages\discord\ext\commands\core.py", line 244, in wrapped
    raise CommandInvokeError(exc) from exc
discord.ext.commands.errors.CommandInvokeError: Command raised an exception: AttributeError: 'dict' object has no attribute 'style'
2024-04-30 01:27:44,900:ERROR:discord.ext.commands.bot: Ignoring exception in command sneek
Traceback (most recent call last):
  File "C:\Users\maddi\PycharmProjects\pythonProject\venv\Lib\site-packages\discord\ext\commands\core.py", line 235, in wrapped
    ret = await coro(*args, **kwargs)
          ^^^^^^^^^^^^^^^^^^^^^^^^^^^
  File "C:\Users\maddi\PycharmProjects\Discord_SneekPeekBot\cogs\sneek_commands.py", line 23, in sneek
    movies = extract.scrape_sneak()
             ^^^^^^^^^^^^^^^^^^^^^^
  File "C:\Users\maddi\PycharmProjects\Discord_SneekPeekBot\jkunze\extract.py", line 31, in scrape_sneak
    chance = columns[1].contents[0].attrs[0]
             ~~~~~~~~~~~~~~~~~~~~~~~~~~~~^^^
KeyError: 0

The above exception was the direct cause of the following exception:

Traceback (most recent call last):
  File "C:\Users\maddi\PycharmProjects\pythonProject\venv\Lib\site-packages\discord\ext\commands\bot.py", line 1350, in invoke
    await ctx.command.invoke(ctx)
  File "C:\Users\maddi\PycharmProjects\pythonProject\venv\Lib\site-packages\discord\ext\commands\core.py", line 1029, in invoke
    await injected(*ctx.args, **ctx.kwargs)  # type: ignore
    ^^^^^^^^^^^^^^^^^^^^^^^^^^^^^^^^^^^^^^^
  File "C:\Users\maddi\PycharmProjects\pythonProject\venv\Lib\site-packages\discord\ext\commands\core.py", line 244, in wrapped
    raise CommandInvokeError(exc) from exc
discord.ext.commands.errors.CommandInvokeError: Command raised an exception: KeyError: 0
2024-04-30 01:29:30,354:ERROR:discord.ext.commands.bot: Ignoring exception in command sneek
Traceback (most recent call last):
  File "C:\Users\maddi\PycharmProjects\pythonProject\venv\Lib\site-packages\discord\ext\commands\core.py", line 235, in wrapped
    ret = await coro(*args, **kwargs)
          ^^^^^^^^^^^^^^^^^^^^^^^^^^^
  File "C:\Users\maddi\PycharmProjects\Discord_SneekPeekBot\cogs\sneek_commands.py", line 23, in sneek
    movies = extract.scrape_sneak()
             ^^^^^^^^^^^^^^^^^^^^^^
  File "C:\Users\maddi\PycharmProjects\Discord_SneekPeekBot\jkunze\extract.py", line 35, in scrape_sneak
    test_chance = columns[1].contents[0].attrs('style')
                  ^^^^^^^^^^^^^^^^^^^^^^^^^^^^^^^^^^^^^
TypeError: 'dict' object is not callable

The above exception was the direct cause of the following exception:

Traceback (most recent call last):
  File "C:\Users\maddi\PycharmProjects\pythonProject\venv\Lib\site-packages\discord\ext\commands\bot.py", line 1350, in invoke
    await ctx.command.invoke(ctx)
  File "C:\Users\maddi\PycharmProjects\pythonProject\venv\Lib\site-packages\discord\ext\commands\core.py", line 1029, in invoke
    await injected(*ctx.args, **ctx.kwargs)  # type: ignore
    ^^^^^^^^^^^^^^^^^^^^^^^^^^^^^^^^^^^^^^^
  File "C:\Users\maddi\PycharmProjects\pythonProject\venv\Lib\site-packages\discord\ext\commands\core.py", line 244, in wrapped
    raise CommandInvokeError(exc) from exc
discord.ext.commands.errors.CommandInvokeError: Command raised an exception: TypeError: 'dict' object is not callable
2024-04-30 01:31:10,178:ERROR:discord.ext.commands.bot: Ignoring exception in command sneek
Traceback (most recent call last):
  File "C:\Users\maddi\PycharmProjects\pythonProject\venv\Lib\site-packages\discord\ext\commands\core.py", line 235, in wrapped
    ret = await coro(*args, **kwargs)
          ^^^^^^^^^^^^^^^^^^^^^^^^^^^
  File "C:\Users\maddi\PycharmProjects\Discord_SneekPeekBot\cogs\sneek_commands.py", line 23, in sneek
    movies = extract.scrape_sneak()
             ^^^^^^^^^^^^^^^^^^^^^^
  File "C:\Users\maddi\PycharmProjects\Discord_SneekPeekBot\jkunze\extract.py", line 35, in scrape_sneak
    test_chance = columns[1].contents[0].attrs('style')
                  ^^^^^^^^^^^^^^^^^^^^^^^^^^^^^^^^^^^^^
TypeError: 'dict' object is not callable

The above exception was the direct cause of the following exception:

Traceback (most recent call last):
  File "C:\Users\maddi\PycharmProjects\pythonProject\venv\Lib\site-packages\discord\ext\commands\bot.py", line 1350, in invoke
    await ctx.command.invoke(ctx)
  File "C:\Users\maddi\PycharmProjects\pythonProject\venv\Lib\site-packages\discord\ext\commands\core.py", line 1029, in invoke
    await injected(*ctx.args, **ctx.kwargs)  # type: ignore
    ^^^^^^^^^^^^^^^^^^^^^^^^^^^^^^^^^^^^^^^
  File "C:\Users\maddi\PycharmProjects\pythonProject\venv\Lib\site-packages\discord\ext\commands\core.py", line 244, in wrapped
    raise CommandInvokeError(exc) from exc
discord.ext.commands.errors.CommandInvokeError: Command raised an exception: TypeError: 'dict' object is not callable
2024-04-30 01:31:35,505:ERROR:discord.ext.commands.bot: Ignoring exception in command sneek
Traceback (most recent call last):
  File "C:\Users\maddi\PycharmProjects\pythonProject\venv\Lib\site-packages\discord\ext\commands\core.py", line 235, in wrapped
    ret = await coro(*args, **kwargs)
          ^^^^^^^^^^^^^^^^^^^^^^^^^^^
  File "C:\Users\maddi\PycharmProjects\Discord_SneekPeekBot\cogs\sneek_commands.py", line 23, in sneek
    movies = extract.scrape_sneak()
             ^^^^^^^^^^^^^^^^^^^^^^
  File "C:\Users\maddi\PycharmProjects\Discord_SneekPeekBot\jkunze\extract.py", line 35, in scrape_sneak
    test_chance = columns[1].contents[0].attrs('style')
                  ^^^^^^^^^^^^^^^^^^^^^^^^^^^^^^^^^^^^^
TypeError: 'dict' object is not callable

The above exception was the direct cause of the following exception:

Traceback (most recent call last):
  File "C:\Users\maddi\PycharmProjects\pythonProject\venv\Lib\site-packages\discord\ext\commands\bot.py", line 1350, in invoke
    await ctx.command.invoke(ctx)
  File "C:\Users\maddi\PycharmProjects\pythonProject\venv\Lib\site-packages\discord\ext\commands\core.py", line 1029, in invoke
    await injected(*ctx.args, **ctx.kwargs)  # type: ignore
    ^^^^^^^^^^^^^^^^^^^^^^^^^^^^^^^^^^^^^^^
  File "C:\Users\maddi\PycharmProjects\pythonProject\venv\Lib\site-packages\discord\ext\commands\core.py", line 244, in wrapped
    raise CommandInvokeError(exc) from exc
discord.ext.commands.errors.CommandInvokeError: Command raised an exception: TypeError: 'dict' object is not callable
2024-04-30 01:36:38,601:ERROR:discord.ext.commands.bot: Ignoring exception in command sneek
Traceback (most recent call last):
  File "C:\Users\maddi\PycharmProjects\pythonProject\venv\Lib\site-packages\discord\ext\commands\core.py", line 235, in wrapped
    ret = await coro(*args, **kwargs)
          ^^^^^^^^^^^^^^^^^^^^^^^^^^^
  File "C:\Users\maddi\PycharmProjects\Discord_SneekPeekBot\cogs\sneek_commands.py", line 23, in sneek
    movies = extract.scrape_sneak()
             ^^^^^^^^^^^^^^^^^^^^^^
  File "C:\Users\maddi\PycharmProjects\Discord_SneekPeekBot\jkunze\extract.py", line 35, in scrape_sneak
    chance_test =chance.get('style').get('width')
                 ^^^^^^^^^^^^^^^^^^^^^^^
AttributeError: 'str' object has no attribute 'get'

The above exception was the direct cause of the following exception:

Traceback (most recent call last):
  File "C:\Users\maddi\PycharmProjects\pythonProject\venv\Lib\site-packages\discord\ext\commands\bot.py", line 1350, in invoke
    await ctx.command.invoke(ctx)
  File "C:\Users\maddi\PycharmProjects\pythonProject\venv\Lib\site-packages\discord\ext\commands\core.py", line 1029, in invoke
    await injected(*ctx.args, **ctx.kwargs)  # type: ignore
    ^^^^^^^^^^^^^^^^^^^^^^^^^^^^^^^^^^^^^^^
  File "C:\Users\maddi\PycharmProjects\pythonProject\venv\Lib\site-packages\discord\ext\commands\core.py", line 244, in wrapped
    raise CommandInvokeError(exc) from exc
discord.ext.commands.errors.CommandInvokeError: Command raised an exception: AttributeError: 'str' object has no attribute 'get'
2024-04-30 02:06:40,260:ERROR:discord.ext.commands.bot: Ignoring exception in command sneek
Traceback (most recent call last):
  File "C:\Users\maddi\PycharmProjects\pythonProject\venv\Lib\site-packages\discord\ext\commands\core.py", line 235, in wrapped
    ret = await coro(*args, **kwargs)
          ^^^^^^^^^^^^^^^^^^^^^^^^^^^
  File "C:\Users\maddi\PycharmProjects\Discord_SneekPeekBot\cogs\sneek_commands.py", line 25, in sneek
    movies = extract.scrape_sneak()
             ^^^^^^^^^^^^^^^^^^^^^^
  File "C:\Users\maddi\PycharmProjects\Discord_SneekPeekBot\jkunze\extract.py", line 42, in scrape_sneak
    rating = imdb.get_rating(imdb_link)
             ^^^^^^^^^^^^^^^^^^^^^^^^^^
  File "C:\Users\maddi\PycharmProjects\Discord_SneekPeekBot\jkunze\imdb.py", line 37, in get_rating
    rating = rating_element.text.strip().split('/')[0]
             ^^^^^^^^^^^^^^^^^^^
AttributeError: 'NoneType' object has no attribute 'text'

The above exception was the direct cause of the following exception:

Traceback (most recent call last):
  File "C:\Users\maddi\PycharmProjects\pythonProject\venv\Lib\site-packages\discord\ext\commands\bot.py", line 1350, in invoke
    await ctx.command.invoke(ctx)
  File "C:\Users\maddi\PycharmProjects\pythonProject\venv\Lib\site-packages\discord\ext\commands\core.py", line 1029, in invoke
    await injected(*ctx.args, **ctx.kwargs)  # type: ignore
    ^^^^^^^^^^^^^^^^^^^^^^^^^^^^^^^^^^^^^^^
  File "C:\Users\maddi\PycharmProjects\pythonProject\venv\Lib\site-packages\discord\ext\commands\core.py", line 244, in wrapped
    raise CommandInvokeError(exc) from exc
discord.ext.commands.errors.CommandInvokeError: Command raised an exception: AttributeError: 'NoneType' object has no attribute 'text'
2024-04-30 02:08:55,379:ERROR:discord.ext.commands.bot: Ignoring exception in command sneek
Traceback (most recent call last):
  File "C:\Users\maddi\PycharmProjects\pythonProject\venv\Lib\site-packages\discord\ext\commands\core.py", line 235, in wrapped
    ret = await coro(*args, **kwargs)
          ^^^^^^^^^^^^^^^^^^^^^^^^^^^
  File "C:\Users\maddi\PycharmProjects\Discord_SneekPeekBot\cogs\sneek_commands.py", line 25, in sneek
    movies = extract.scrape_sneak()
             ^^^^^^^^^^^^^^^^^^^^^^
  File "C:\Users\maddi\PycharmProjects\Discord_SneekPeekBot\jkunze\extract.py", line 42, in scrape_sneak
    rating = imdb.get_rating(imdb_link)
             ^^^^^^^^^^^^^^^^^^^^^^^^^^
  File "C:\Users\maddi\PycharmProjects\Discord_SneekPeekBot\jkunze\imdb.py", line 37, in get_rating
    rating = rating_element.text.strip().split('/')[0]
             ^^^^^^^^^^^^^^^^^^^
AttributeError: 'NoneType' object has no attribute 'text'

The above exception was the direct cause of the following exception:

Traceback (most recent call last):
  File "C:\Users\maddi\PycharmProjects\pythonProject\venv\Lib\site-packages\discord\ext\commands\bot.py", line 1350, in invoke
    await ctx.command.invoke(ctx)
  File "C:\Users\maddi\PycharmProjects\pythonProject\venv\Lib\site-packages\discord\ext\commands\core.py", line 1029, in invoke
    await injected(*ctx.args, **ctx.kwargs)  # type: ignore
    ^^^^^^^^^^^^^^^^^^^^^^^^^^^^^^^^^^^^^^^
  File "C:\Users\maddi\PycharmProjects\pythonProject\venv\Lib\site-packages\discord\ext\commands\core.py", line 244, in wrapped
    raise CommandInvokeError(exc) from exc
discord.ext.commands.errors.CommandInvokeError: Command raised an exception: AttributeError: 'NoneType' object has no attribute 'text'
2024-04-30 02:14:01,426:ERROR:discord.ext.commands.bot: Ignoring exception in command sneek
Traceback (most recent call last):
  File "C:\Users\maddi\PycharmProjects\pythonProject\venv\Lib\site-packages\discord\ext\commands\core.py", line 235, in wrapped
    ret = await coro(*args, **kwargs)
          ^^^^^^^^^^^^^^^^^^^^^^^^^^^
  File "C:\Users\maddi\PycharmProjects\Discord_SneekPeekBot\cogs\sneek_commands.py", line 25, in sneek
    movies = extract.scrape_sneak()
             ^^^^^^^^^^^^^^^^^^^^^^
  File "C:\Users\maddi\PycharmProjects\Discord_SneekPeekBot\jkunze\extract.py", line 42, in scrape_sneak
    rating = imdb.get_rating(imdb_link)
             ^^^^^^^^^^^^^^^^^^^^^^^^^^
  File "C:\Users\maddi\PycharmProjects\Discord_SneekPeekBot\jkunze\imdb.py", line 37, in get_rating
    rating = rating_element.text.strip().split('/')[0]
             ^^^^^^^^^^^^^^^^^^^
AttributeError: 'NoneType' object has no attribute 'text'

The above exception was the direct cause of the following exception:

Traceback (most recent call last):
  File "C:\Users\maddi\PycharmProjects\pythonProject\venv\Lib\site-packages\discord\ext\commands\bot.py", line 1350, in invoke
    await ctx.command.invoke(ctx)
  File "C:\Users\maddi\PycharmProjects\pythonProject\venv\Lib\site-packages\discord\ext\commands\core.py", line 1029, in invoke
    await injected(*ctx.args, **ctx.kwargs)  # type: ignore
    ^^^^^^^^^^^^^^^^^^^^^^^^^^^^^^^^^^^^^^^
  File "C:\Users\maddi\PycharmProjects\pythonProject\venv\Lib\site-packages\discord\ext\commands\core.py", line 244, in wrapped
    raise CommandInvokeError(exc) from exc
discord.ext.commands.errors.CommandInvokeError: Command raised an exception: AttributeError: 'NoneType' object has no attribute 'text'
2024-04-30 02:14:09,371:ERROR:discord.client: Ignoring exception in on_ready
Traceback (most recent call last):
  File "C:\Users\maddi\PycharmProjects\pythonProject\venv\Lib\site-packages\discord\client.py", line 441, in _run_event
    await coro(*args, **kwargs)
  File "C:\Users\maddi\PycharmProjects\Discord_SneekPeekBot\sneekbot.py", line 35, in on_ready
    await self.add_cog(cogs_example.ExampleCog(self))
  File "C:\Users\maddi\PycharmProjects\pythonProject\venv\Lib\site-packages\discord\ext\commands\bot.py", line 777, in add_cog
    raise discord.ClientException(f'Cog named {cog_name!r} already loaded')
discord.errors.ClientException: Cog named 'ExampleCog' already loaded
2024-04-30 02:17:14,277:ERROR:discord.ext.commands.bot: Ignoring exception in command sneek
Traceback (most recent call last):
  File "C:\Users\maddi\PycharmProjects\pythonProject\venv\Lib\site-packages\discord\ext\commands\core.py", line 235, in wrapped
    ret = await coro(*args, **kwargs)
          ^^^^^^^^^^^^^^^^^^^^^^^^^^^
  File "C:\Users\maddi\PycharmProjects\Discord_SneekPeekBot\cogs\sneek_commands.py", line 25, in sneek
    movies = extract.scrape_sneak()
             ^^^^^^^^^^^^^^^^^^^^^^
  File "C:\Users\maddi\PycharmProjects\Discord_SneekPeekBot\jkunze\extract.py", line 42, in scrape_sneak
    rating = imdb.get_rating(imdb_link)
             ^^^^^^^^^^^^^^^^^^^^^^^^^^
  File "C:\Users\maddi\PycharmProjects\Discord_SneekPeekBot\jkunze\imdb.py", line 37, in get_rating
    rating = rating_element.text.strip().split('/')[0]
             ^^^^^^^^^^^^^^^^^^^
AttributeError: 'NoneType' object has no attribute 'text'

The above exception was the direct cause of the following exception:

Traceback (most recent call last):
  File "C:\Users\maddi\PycharmProjects\pythonProject\venv\Lib\site-packages\discord\ext\commands\bot.py", line 1350, in invoke
    await ctx.command.invoke(ctx)
  File "C:\Users\maddi\PycharmProjects\pythonProject\venv\Lib\site-packages\discord\ext\commands\core.py", line 1029, in invoke
    await injected(*ctx.args, **ctx.kwargs)  # type: ignore
    ^^^^^^^^^^^^^^^^^^^^^^^^^^^^^^^^^^^^^^^
  File "C:\Users\maddi\PycharmProjects\pythonProject\venv\Lib\site-packages\discord\ext\commands\core.py", line 244, in wrapped
    raise CommandInvokeError(exc) from exc
discord.ext.commands.errors.CommandInvokeError: Command raised an exception: AttributeError: 'NoneType' object has no attribute 'text'
2024-04-30 02:17:22,199:ERROR:discord.client: Ignoring exception in on_ready
Traceback (most recent call last):
  File "C:\Users\maddi\PycharmProjects\pythonProject\venv\Lib\site-packages\discord\client.py", line 441, in _run_event
    await coro(*args, **kwargs)
  File "C:\Users\maddi\PycharmProjects\Discord_SneekPeekBot\sneekbot.py", line 35, in on_ready
    await self.add_cog(cogs_example.ExampleCog(self))
  File "C:\Users\maddi\PycharmProjects\pythonProject\venv\Lib\site-packages\discord\ext\commands\bot.py", line 777, in add_cog
    raise discord.ClientException(f'Cog named {cog_name!r} already loaded')
discord.errors.ClientException: Cog named 'ExampleCog' already loaded
2024-04-30 02:29:36,690:ERROR:discord.ext.commands.bot: Ignoring exception in command sneek
Traceback (most recent call last):
  File "C:\Users\maddi\PycharmProjects\pythonProject\venv\Lib\site-packages\discord\ext\commands\core.py", line 235, in wrapped
    ret = await coro(*args, **kwargs)
          ^^^^^^^^^^^^^^^^^^^^^^^^^^^
  File "C:\Users\maddi\PycharmProjects\Discord_SneekPeekBot\cogs\sneek_commands.py", line 25, in sneek
    movies = extract.scrape_sneak()
             ^^^^^^^^^^^^^^^^^^^^^^
  File "C:\Users\maddi\PycharmProjects\Discord_SneekPeekBot\jkunze\extract.py", line 42, in scrape_sneak
    rating = imdb.get_rating(imdb_link)
             ^^^^^^^^^^^^^^^^^^^^^^^^^^
  File "C:\Users\maddi\PycharmProjects\Discord_SneekPeekBot\jkunze\imdb.py", line 37, in get_rating
    rating = rating_element.text.strip().split('/')[0]
             ^^^^^^^^^^^^^^^^^^^
AttributeError: 'NoneType' object has no attribute 'text'

The above exception was the direct cause of the following exception:

Traceback (most recent call last):
  File "C:\Users\maddi\PycharmProjects\pythonProject\venv\Lib\site-packages\discord\ext\commands\bot.py", line 1350, in invoke
    await ctx.command.invoke(ctx)
  File "C:\Users\maddi\PycharmProjects\pythonProject\venv\Lib\site-packages\discord\ext\commands\core.py", line 1029, in invoke
    await injected(*ctx.args, **ctx.kwargs)  # type: ignore
    ^^^^^^^^^^^^^^^^^^^^^^^^^^^^^^^^^^^^^^^
  File "C:\Users\maddi\PycharmProjects\pythonProject\venv\Lib\site-packages\discord\ext\commands\core.py", line 244, in wrapped
    raise CommandInvokeError(exc) from exc
discord.ext.commands.errors.CommandInvokeError: Command raised an exception: AttributeError: 'NoneType' object has no attribute 'text'
2024-04-30 02:35:10,394:ERROR:discord.ext.commands.bot: Ignoring exception in command sneek
Traceback (most recent call last):
  File "C:\Users\maddi\PycharmProjects\pythonProject\venv\Lib\site-packages\discord\ext\commands\core.py", line 235, in wrapped
    ret = await coro(*args, **kwargs)
          ^^^^^^^^^^^^^^^^^^^^^^^^^^^
  File "C:\Users\maddi\PycharmProjects\Discord_SneekPeekBot\cogs\sneek_commands.py", line 25, in sneek
    movies = extract.scrape_sneak()
             ^^^^^^^^^^^^^^^^^^^^^^
  File "C:\Users\maddi\PycharmProjects\Discord_SneekPeekBot\jkunze\extract.py", line 42, in scrape_sneak
    rating = imdb.get_rating(imdb_link)
             ^^^^^^^^^^^^^^^^^^^^^^^^^^
  File "C:\Users\maddi\PycharmProjects\Discord_SneekPeekBot\jkunze\imdb.py", line 37, in get_rating
    rating = rating_element.text.strip().split('/')[0]
             ^^^^^^^^^^^^^^^^^^^
AttributeError: 'NoneType' object has no attribute 'text'

The above exception was the direct cause of the following exception:

Traceback (most recent call last):
  File "C:\Users\maddi\PycharmProjects\pythonProject\venv\Lib\site-packages\discord\ext\commands\bot.py", line 1350, in invoke
    await ctx.command.invoke(ctx)
  File "C:\Users\maddi\PycharmProjects\pythonProject\venv\Lib\site-packages\discord\ext\commands\core.py", line 1029, in invoke
    await injected(*ctx.args, **ctx.kwargs)  # type: ignore
    ^^^^^^^^^^^^^^^^^^^^^^^^^^^^^^^^^^^^^^^
  File "C:\Users\maddi\PycharmProjects\pythonProject\venv\Lib\site-packages\discord\ext\commands\core.py", line 244, in wrapped
    raise CommandInvokeError(exc) from exc
discord.ext.commands.errors.CommandInvokeError: Command raised an exception: AttributeError: 'NoneType' object has no attribute 'text'
2024-04-30 02:37:27,051:ERROR:discord.ext.commands.bot: Ignoring exception in command sneek
Traceback (most recent call last):
  File "C:\Users\maddi\PycharmProjects\pythonProject\venv\Lib\site-packages\discord\ext\commands\core.py", line 235, in wrapped
    ret = await coro(*args, **kwargs)
          ^^^^^^^^^^^^^^^^^^^^^^^^^^^
  File "C:\Users\maddi\PycharmProjects\Discord_SneekPeekBot\cogs\sneek_commands.py", line 25, in sneek
    movies = extract.scrape_sneak()
             ^^^^^^^^^^^^^^^^^^^^^^
  File "C:\Users\maddi\PycharmProjects\Discord_SneekPeekBot\jkunze\extract.py", line 42, in scrape_sneak
    rating = imdb.get_rating(imdb_link)
             ^^^^^^^^^^^^^^^^^^^^^^^^^^
  File "C:\Users\maddi\PycharmProjects\Discord_SneekPeekBot\jkunze\imdb.py", line 37, in get_rating
    rating = rating_element.text.strip().split('/')[0]
             ^^^^^^^^^^^^^^^^^^^
AttributeError: 'NoneType' object has no attribute 'text'

The above exception was the direct cause of the following exception:

Traceback (most recent call last):
  File "C:\Users\maddi\PycharmProjects\pythonProject\venv\Lib\site-packages\discord\ext\commands\bot.py", line 1350, in invoke
    await ctx.command.invoke(ctx)
  File "C:\Users\maddi\PycharmProjects\pythonProject\venv\Lib\site-packages\discord\ext\commands\core.py", line 1029, in invoke
    await injected(*ctx.args, **ctx.kwargs)  # type: ignore
    ^^^^^^^^^^^^^^^^^^^^^^^^^^^^^^^^^^^^^^^
  File "C:\Users\maddi\PycharmProjects\pythonProject\venv\Lib\site-packages\discord\ext\commands\core.py", line 244, in wrapped
    raise CommandInvokeError(exc) from exc
discord.ext.commands.errors.CommandInvokeError: Command raised an exception: AttributeError: 'NoneType' object has no attribute 'text'
2024-04-30 02:37:27,057:ERROR:discord.client: Attempting a reconnect in 0.80s
Traceback (most recent call last):
  File "C:\Users\maddi\PycharmProjects\pythonProject\venv\Lib\site-packages\discord\client.py", line 659, in connect
    await self.ws.poll_event()
  File "C:\Users\maddi\PycharmProjects\pythonProject\venv\Lib\site-packages\discord\gateway.py", line 646, in poll_event
    raise ConnectionClosed(self.socket, shard_id=self.shard_id, code=code) from None
discord.errors.ConnectionClosed: Shard ID None WebSocket closed with 1000
2024-04-30 02:38:42,231:ERROR:discord.ext.commands.bot: Ignoring exception in command sneek
Traceback (most recent call last):
  File "C:\Users\maddi\PycharmProjects\pythonProject\venv\Lib\site-packages\discord\ext\commands\core.py", line 235, in wrapped
    ret = await coro(*args, **kwargs)
          ^^^^^^^^^^^^^^^^^^^^^^^^^^^
  File "C:\Users\maddi\PycharmProjects\Discord_SneekPeekBot\cogs\sneek_commands.py", line 25, in sneek
    movies = extract.scrape_sneak()
             ^^^^^^^^^^^^^^^^^^^^^^
  File "C:\Users\maddi\PycharmProjects\Discord_SneekPeekBot\jkunze\extract.py", line 42, in scrape_sneak
    rating = imdb.get_rating(imdb_link)
             ^^^^^^^^^^^^^^^^^^^^^^^^^^
  File "C:\Users\maddi\PycharmProjects\Discord_SneekPeekBot\jkunze\imdb.py", line 37, in get_rating
    rating = rating_element.text.strip().split('/')[0]
             ^^^^^^^^^^^^^^^^^^^
AttributeError: 'NoneType' object has no attribute 'text'

The above exception was the direct cause of the following exception:

Traceback (most recent call last):
  File "C:\Users\maddi\PycharmProjects\pythonProject\venv\Lib\site-packages\discord\ext\commands\bot.py", line 1350, in invoke
    await ctx.command.invoke(ctx)
  File "C:\Users\maddi\PycharmProjects\pythonProject\venv\Lib\site-packages\discord\ext\commands\core.py", line 1029, in invoke
    await injected(*ctx.args, **ctx.kwargs)  # type: ignore
    ^^^^^^^^^^^^^^^^^^^^^^^^^^^^^^^^^^^^^^^
  File "C:\Users\maddi\PycharmProjects\pythonProject\venv\Lib\site-packages\discord\ext\commands\core.py", line 244, in wrapped
    raise CommandInvokeError(exc) from exc
discord.ext.commands.errors.CommandInvokeError: Command raised an exception: AttributeError: 'NoneType' object has no attribute 'text'
2024-04-30 02:39:34,396:ERROR:discord.ext.commands.bot: Ignoring exception in command sneek
Traceback (most recent call last):
  File "C:\Users\maddi\PycharmProjects\pythonProject\venv\Lib\site-packages\discord\ext\commands\core.py", line 235, in wrapped
    ret = await coro(*args, **kwargs)
          ^^^^^^^^^^^^^^^^^^^^^^^^^^^
  File "C:\Users\maddi\PycharmProjects\Discord_SneekPeekBot\cogs\sneek_commands.py", line 25, in sneek
    movies = extract.scrape_sneak()
             ^^^^^^^^^^^^^^^^^^^^^^
  File "C:\Users\maddi\PycharmProjects\Discord_SneekPeekBot\jkunze\extract.py", line 21, in scrape_sneak
    for row in soup.find_all("tr", class_="lvct2")[10]:
               ~~~~~~~~~~~~~~~~~~~~~~~~~~~~~~~~~~~^^^^
IndexError: list index out of range

The above exception was the direct cause of the following exception:

Traceback (most recent call last):
  File "C:\Users\maddi\PycharmProjects\pythonProject\venv\Lib\site-packages\discord\ext\commands\bot.py", line 1350, in invoke
    await ctx.command.invoke(ctx)
  File "C:\Users\maddi\PycharmProjects\pythonProject\venv\Lib\site-packages\discord\ext\commands\core.py", line 1029, in invoke
    await injected(*ctx.args, **ctx.kwargs)  # type: ignore
    ^^^^^^^^^^^^^^^^^^^^^^^^^^^^^^^^^^^^^^^
  File "C:\Users\maddi\PycharmProjects\pythonProject\venv\Lib\site-packages\discord\ext\commands\core.py", line 244, in wrapped
    raise CommandInvokeError(exc) from exc
discord.ext.commands.errors.CommandInvokeError: Command raised an exception: IndexError: list index out of range
